Workbook

Sheet Charts
A3: Row Labels | B3: Sum of Sales | D3: Row Labels | E3: Sum of Sales | G3: Row Labels | H3: Sum of Sales
A4: Furniture | B4: 728658.58 | D4: Central | E4: 492646.91 | G4: Accessories | H4: 164186.7
A5: Office Supplies | B5: 705422.33 | D5: East | E5: 669518.73 | G5: Appliances | H5: 104618.4
A6: Technology | B6: 827455.87 | D6: South | E6: 389151.46 | G6: Art | H6: 26705.41
A7: Grand Total | B7: 2261536.8 | D7: West | E7: 710219.68 | G7: Binders | H7: 200028.79
D8: Grand Total | E8: 2261536.8 | G8: Bookcases | H8: 113813.2
G9: Chairs | H9: 322822.73
G10: Copiers | H10: 146248.09
G11: Envelopes | H11: 16128.046
G12: Fasteners | H12: 3001.96
G13: Furnishings | H13: 89212.018
G14: Labels | H14: 12347.726
G15: Machines | H15: 189238.63
G16: Paper | H16: 76828.304
G17: Phones | H17: 327782.45
G18: Storage | H18: 219343.39
G19: Supplies | H19: 46420.308
G20: Tables | H20: 202810.63
G21: Grand Total | H21: 2261536.8
A39: Sum of Sales | B39: Column Labels | G39: Row Labels | H39: Sum of Sales
A40: Row Labels | B40: Consumer | C40: Corporate | D40: Home Office | E40: Grand Total | G40: Sean Miller | H40: 25043.05
A41: Central | B41: 250210.52 | C41: 152031.5 | D41: 90404.894 | E41: 492646.91 | G41: Tamara Chand | H41: 19052.218
A42: East | B42: 347906.61 | C42: 195897.42 | D42: 125714.7 | E42: 669518.73 | G42: Raymond Buch | H42: 15117.339
A43: South | B43: 194702.21 | C43: 120546.87 | D43: 73902.372 | E43: 389151.46 | G43: Tom Ashbrook | H43: 14595.62
A44: West | B44: 355241.19 | C44: 220018.28 | D44: 134960.21 | E44: 710219.68 | G44: Adrian Barton | H44: 14473.571
A45: Grand Total | B45: 1148060.5 | C45: 688494.07 | D45: 424982.18 | E45: 2261536.8 | G45: Ken Lonsdale | H45: 14175.229
G46: Sanjit Chand | H46: 14142.334
A47: Row Labels | B47: Sum of Sales | G47: Hunter Lopez | H47: 12873.298
A48: 2015 | B48: 479856.21 | G48: Sanjit Engle | H48: 12209.438
A49: Jan | B49: 14205.707 | G49: Christopher Conant | H49: 12129.072
A50: Feb | B50: 4519.892 | G50: Grand Total | H50: 153811.17
A51: Mar | B51: 55205.797
A52: Apr | B52: 27906.855
A53: May | B53: 23644.303
A54: Jun | B54: 34322.936
A55: Jul | B55: 33781.543
A56: Aug | B56: 27117.536
A57: Sep | B57: 81623.527
A58: Oct | B58: 31453.393
A59: Nov | B59: 77907.661
...

Sheet train
A1: Row ID | B1: Order ID | C1: Order Date | D1: Ship Date | E1: Ship Mode | F1: Customer ID | G1: Customer Name | H1: Segment | I1: Country | J1: City | K1: State | L1: Postal Code | M1: Region | N1: Product ID | O1: Category | P1: Sub-Category | Q1: Product Name | R1: Sales | S1: Sum | T1: Count | U1: If
A2: 1 | B2: CA-2017-152156 | C2: 43047 | D2: 43050 | E2: Second Class | F2: CG-12520 | G2: Claire Gute | H2: Consumer | I2: United States | J2: Henderson | K2: Kentucky | L2: 42420 | M2: South | N2: FUR-BO-10001798 | O2: Furniture | P2: Bookcases | Q2: Bush Somerset Collection Bookcase | R2: 261.96 | S2: =SUM(R2:R9801) -> 2261536.8 | T2: =COUNT(R2:R9801) -> 9800 | U2: =IF(R2>=500,"High","Low") -> Low
A3: 2 | B3: CA-2017-152156 | C3: 43047 | D3: 43050 | E3: Second Class | F3: CG-12520 | G3: Claire Gute | H3: Consumer | I3: United States | J3: Henderson | K3: Kentucky | L3: 42420 | M3: South | N3: FUR-CH-10000454 | O3: Furniture | P3: Chairs | Q3: Hon Deluxe Fabric Upholstered Stacking Chairs, Rounded Back | R3: 731.94 | S3: =SUM(R3:R9802) -> 2261274.8 | T3: =COUNT(R3:R9802) -> 9799 | U3: =IF(R3>=500,"High","Low") -> High
A4: 3 | B4: CA-2017-138688 | C4: 42898 | D4: 42902 | E4: Second Class | F4: DV-13045 | G4: Darrin Van Huff | H4: Corporate | I4: United States | J4: Los Angeles | K4: California | L4: 90036 | M4: West | N4: OFF-LA-10000240 | O4: Office Supplies | P4: Labels | Q4: Self-Adhesive Address Labels for Typewriters by Universal | R4: 14.62 | S4: =SUM(R4:R9803) -> 2260542.9 | T4: =COUNT(R4:R9803) -> 9798 | U4: =IF(R4>=500,"High","Low") -> Low
A5: 4 | B5: US-2016-108966 | C5: 42654 | D5: 42661 | E5: Standard Class | F5: SO-20335 | G5: Sean O'Donnell | H5: Consumer | I5: United States | J5: Fort Lauderdale | K5: Florida | L5: 33311 | M5: South | N5: FUR-TA-10000577 | O5: Furniture | P5: Tables | Q5: Bretford CR4500 Series Slim Rectangular Table | R5: 957.5775 | S5: =SUM(R5:R9804) -> 2260528.3 | T5: =COUNT(R5:R9804) -> 9797 | U5: =IF(R5>=500,"High","Low") -> High
A6: 5 | B6: US-2016-108966 | C6: 42654 | D6: 42661 | E6: Standard Class | F6: SO-20335 | G6: Sean O'Donnell | H6: Consumer | I6: United States | J6: Fort Lauderdale | K6: Florida | L6: 33311 | M6: South | N6: OFF-ST-10000760 | O6: Office Supplies | P6: Storage | Q6: Eldon Fold 'N Roll Cart System | R6: 22.368 | S6: =SUM(R6:R9805) -> 2259570.7 | T6: =COUNT(R6:R9805) -> 9796 | U6: =IF(R6>=500,"High","Low") -> Low
A7: 6 | B7: CA-2015-115812 | C7: 42164 | D7: 42169 | E7: Standard Class | F7: BH-11710 | G7: Brosina Hoffman | H7: Consumer | I7: United States | J7: Los Angeles | K7: California | L7: 90032 | M7: West | N7: FUR-FU-10001487 | O7: Furniture | P7: Furnishings | Q7: Eldon Expressions Wood and Plastic Desk Accessories, Cherry Wood | R7: 48.86 | S7: =SUM(R7:R9806) -> 2259548.3 | T7: =COUNT(R7:R9806) -> 9795 | U7: =IF(R7>=500,"High","Low") -> Low
A8: 7 | B8: CA-2015-115812 | C8: 42164 | D8: 42169 | E8: Standard Class | F8: BH-11710 | G8: Brosina Hoffman | H8: Consumer | I8: United States | J8: Los Angeles | K8: California | L8: 90032 | M8: West | N8: OFF-AR-10002833 | O8: Office Supplies | P8: Art | Q8: Newell 322 | R8: 7.28 | S8: =SUM(R8:R9807) -> 2259499.5 | T8: =COUNT(R8:R9807) -> 9794 | U8: =IF(R8>=500,"High","Low") -> Low
A9: 8 | B9: CA-2015-115812 | C9: 42164 | D9: 42169 | E9: Standard Class | F9: BH-11710 | G9: Brosina Hoffman | H9: Consumer | I9: United States | J9: Los Angeles | K9: California | L9: 90032 | M9: West | N9: TEC-PH-10002275 | O9: Technology | P9: Phones | Q9: Mitel 5320 IP Phone VoIP phone | R9: 907.152 | S9: =SUM(R9:R9808) -> 2259492.2 | T9: =COUNT(R9:R9808) -> 9793 | U9: =IF(R9>=500,"High","Low") -> High
A10: 9 | B10: CA-2015-115812 | C10: 42164 | D10: 42169 | E10: Standard Class | F10: BH-11710 | G10: Brosina Hoffman | H10: Consumer | I10: United States | J10: Los Angeles | K10: California | L10: 90032 | M10: West | N10: OFF-BI-10003910 | O10: Office Supplies | P10: Binders | Q10: DXL Angle-View Binders with Locking Rings by Samsill | R10: 18.504 | S10: =SUM(R10:R9809) -> 2258585 | T10: =COUNT(R10:R9809) -> 9792 | U10: =IF(R10>=500,"High","Low") -> Low
A11: 10 | B11: CA-2015-115812 | C11: 42164 | D11: 42169 | E11: Standard Class | F11: BH-11710 | G11: Brosina Hoffman | H11: Consumer | I11: United States | J11: Los Angeles | K11: California | L11: 90032 | M11: West | N11: OFF-AP-10002892 | O11: Office Supplies | P11: Appliances | Q11: Belkin F5C206VTEL 6 Outlet Surge | R11: 114.9 | S11: =SUM(R11:R9810) -> 2258566.5 | T11: =COUNT(R11:R9810) -> 9791 | U11: =IF(R11>=500,"High","Low") -> Low
A12: 11 | B12: CA-2015-115812 | C12: 42164 | D12: 42169 | E12: Standard Class | F12: BH-11710 | G12: Brosina Hoffman | H12: Consumer | I12: United States | J12: Los Angeles | K12: California | L12: 90032 | M12: West | N12: FUR-TA-10001539 | O12: Furniture | P12: Tables | Q12: Chromcraft Rectangular Conference Tables | R12: 1706.184 | S12: =SUM(R12:R9811) -> 2258451.6 | T12: =COUNT(R12:R9811) -> 9790 | U12: =IF(R12>=500,"High","Low") -> High
A13: 12 | B13: CA-2015-115812 | C13: 42164 | D13: 42169 | E13: Standard Class | F13: BH-11710 | G13: Brosina Hoffman | H13: Consumer | I13: United States | J13: Los Angeles | K13: California | L13: 90032 | M13: West | N13: TEC-PH-10002033 | O13: Technology | P13: Phones | Q13: Konftel 250 ConferenceÂ phoneÂ - Charcoal black | R13: 911.424 | S13: =SUM(R13:R9812) -> 2256745.4 | T13: =COUNT(R13:R9812) -> 9789 | U13: =IF(R13>=500,"High","Low") -> High
... A2235: 2234 | B2235: CA-2016-123232 | C2235: 42718 | D2235: 42720 | E2235: Second Class | F2235: DJ-13630 | G2235: Doug Jacobs | H2235: Consumer | I2235: United States | J2235: Portland | K2235: Oregon | L2235: 97206 | M2235: West | N2235: TEC-PH-10001051 | O2235: Technology | P2235: Phones | Q2235: HTC One | R2235: 319.968 | S2235: =SUM(R2235:R12034) -> 1762199.5 | T2235: =COUNT(R2235:R12034) -> 7567 | U2235: =IF(R2235>=500,"High","Low") -> Low
A2236: 2235 | B2236: CA-2018-104066 | C2236: 43439 | D2236: 43444 | E2236: Standard Class | F2236: QJ-19255 | G2236: Quincy Jones | H2236: Corporate | I2236: United States | J2236: Burlington | K2236: Vermont | M2236: East | N2236: TEC-AC-10001013 | O2236: Technology | P2236: Accessories | Q2236: Logitech ClearChat Comfort/USB Headset H390 | R2236: 205.03 | S2236: =SUM(R2236:R12035) -> 1761879.5 | T2236: =COUNT(R2236:R12035) -> 7566 | U2236: =IF(R2236>=500,"High","Low") -> Low
A2237: 2236 | B2237: CA-2016-145849 | C2237: 42628 | D2237: 42630 | E2237: Second Class | F2237: CT-11995 | G2237: Carol Triggs | H2237: Consumer | I2237: United States | J2237: Indianapolis | K2237: Indiana | L2237: 46203 | M2237: Central | N2237: OFF-ST-10000025 | O2237: Office Supplies | P2237: Storage | Q2237: Fellowes Stor/Drawer Steel Plus Storage Drawers | R2237: 190.86 | S2237: =SUM(R2237:R12036) -> 1761674.5 | T2237: =COUNT(R2237:R12036) -> 7565 | U2237: =IF(R2237>=500,"High","Low") -> Low
A2238: 2237 | B2238: CA-2016-145849 | C2238: 42628 | D2238: 42630 | E2238: Second Class | F2238: CT-11995 | G2238: Carol Triggs | H2238: Consumer | I2238: United States | J2238: Indianapolis | K2238: Indiana | L2238: 46203 | M2238: Central | N2238: OFF-AR-10000817 | O2238: Office Supplies | P2238: Art | Q2238: Manco Dry-Lighter Erasable Highlighter | R2238: 24.32 | S2238: =SUM(R2238:R12037) -> 1761483.6 | T2238: =COUNT(R2238:R12037) -> 7564 | U2238: =IF(R2238>=500,"High","Low") -> Low
A2239: 2238 | B2239: CA-2017-122322 | C2239: 42931 | D2239: 42937 | E2239: Standard Class | F2239: RH-19510 | G2239: Rick Huthwaite | H2239: Home Office | I2239: United States | J2239: Provo | K2239: Utah | L2239: 84604 | M2239: West | N2239: OFF-SU-10000952 | O2239: Office Supplies | P2239: Supplies | Q2239: Fiskars Home & Office Scissors | R2239: 44.4 | S2239: =SUM(R2239:R12038) -> 1761459.3 | T2239: =COUNT(R2239:R12038) -> 7563 | U2239: =IF(R2239>=500,"High","Low") -> Low
A2240: 2239 | B2240: CA-2018-166849 | C2240: 43210 | D2240: 43216 | E2240: Standard Class | F2240: SJ-20125 | G2240: Sanjit Jacobs | H2240: Home Office | I2240: United States | J2240: Chicago | K2240: Illinois | L2240: 60610 | M2240: Central | N2240: FUR-FU-10004597 | O2240: Furniture | P2240: Furnishings | Q2240: Eldon Cleatmat Chair Mats for Medium Pile Carpets | R2240: 44.4 | S2240: =SUM(R2240:R12039) -> 1761414.9 | T2240: =COUNT(R2240:R12039) -> 7562 | U2240: =IF(R2240>=500,"High","Low") -> Low
A2241: 2240 | B2241: CA-2017-146633 | C2241: 43054 | D2241: 43056 | E2241: Second Class | F2241: TG-21310 | G2241: Toby Gnade | H2241: Consumer | I2241: United States | J2241: Los Angeles | K2241: California | L2241: 90049 | M2241: West | N2241: OFF-BI-10003527 | O2241: Office Supplies | P2241: Binders | Q2241: Fellowes PB500 Electric Punch Plastic Comb Binding Machine with Manual Bind | R2241: 1016.792 | S2241: =SUM(R2241:R12040) -> 1761370.5 | T2241: =COUNT(R2241:R12040) -> 7561 | U2241: =IF(R2241>=500,"High","Low") -> High
A2242: 2241 | B2242: CA-2017-146633 | C2242: 43054 | D2242: 43056 | E2242: Second Class | F2242: TG-21310 | G2242: Toby Gnade | H2242: Consumer | I2242: United States | J2242: Los Angeles | K2242: California | L2242: 90049 | M2242: West | N2242: OFF-BI-10002982 | O2242: Office Supplies | P2242: Binders | Q2242: Avery Self-Adhesive Photo Pockets for Polaroid Photos | R2242: 38.136 | S2242: =SUM(R2242:R12041) -> 1760353.7 | T2242: =COUNT(R2242:R12041) -> 7560 | U2242: =IF(R2242>=500,"High","Low") -> Low
A2243: 2242 | B2243: US-2017-126893 | C2243: 43065 | D2243: 43070 | E2243: Standard Class | F2243: CT-11995 | G2243: Carol Triggs | H2243: Consumer | I2243: United States | J2243: Philadelphia | K2243: Pennsylvania | L2243: 19134 | M2243: East | N2243: TEC-PH-10004165 | O2243: Technology | P2243: Phones | Q2243: Mitel MiVoice 5330e IP Phone | R2243: 494.982 | S2243: =SUM(R2243:R12042) -> 1760315.6 | T2243: =COUNT(R2243:R12042) -> 7559 | U2243: =IF(R2243>=500,"High","Low") -> Low
A2244: 2243 | B2244: CA-2018-103380 | C2244: 43425 | D2244: 43429 | E2244: Standard Class | F2244: BF-11005 | G2244: Barry Franz | H2244: Home Office | I2244: United States | J2244: Pasadena | K2244: California | L2244: 91104 | M2244: West | N2244: OFF-ST-10003442 | O2244: Office Supplies | P2244: Storage | Q2244: Eldon Portable Mobile Manager | R2244: 56.56 | S2244: =SUM(R2244:R12043) -> 1759820.6 | T2244: =COUNT(R2244:R12043) -> 7558 | U2244: =IF(R2244>=500,"High","Low") -> Low
A2245: 2244 | B2245: CA-2018-103380 | C2245: 43425 | D2245: 43429 | E2245: Standard Class | F2245: BF-11005 | G2245: Barry Franz | H2245: Home Office | I2245: United States | J2245: Pasadena | K2245: California | L2245: 91104 | M2245: West | N2245: OFF-AR-10003856 | O2245: Office Supplies | P2245: Art | Q2245: Newell 344 | R2245: 5.56 | S2245: =SUM(R2245:R12044) -> 1759764.1 | T2245: =COUNT(R2245:R12044) -> 7557 | U2245: =IF(R2245>=500,"High","Low") -> Low
A2246: 2245 | B2246: CA-2018-103380 | C2246: 43425 | D2246: 43429 | E2246: Standard Class | F2246: BF-11005 | G2246: Barry Franz | H2246: Home Office | I2246: United States | J2246: Pasadena | K2246: California | L2246: 91104 | M2246: West | N2246: OFF-FA-10004248 | O2246: Office Supplies | P2246: Fasteners | Q2246: Advantus T-Pin Paper Clips | R2246: 9.02 | S2246: =SUM(R2246:R12045) -> 1759758.5 | T2246: =COUNT(R2246:R12045) -> 7556 | U2246: =IF(R2246>=500,"High","Low") -> Low
A2247: 2246 | B2247: CA-2018-103380 | C2247: 43425 | D2247: 43429 | E2247: Standard Class | F2247: BF-11005 | G2247: Barry Franz | H2247: Home Office | I2247: United States | J2247: Pasadena | K2247: California | L2247: 91104 | M2247: West | N2247: OFF-AP-10001492 | O2247: Office Supplies | P2247: Appliances | Q2247: Acco Six-Outlet Power Strip, 4' Cord Length | R2247: 8.62 | S2247: =SUM(R2247:R12046) -> 1759749.5 | T2247: =COUNT(R2247:R12046) -> 7555 | U2247: =IF(R2247>=500,"High","Low") -> Low
A2248: 2247 | B2248: CA-2018-103380 | C2248: 43425 | D2248: 43429 | E2248: Standard Class | F2248: BF-11005 | G2248: Barry Franz | H2248: Home Office | I2248: United States | J2248: Pasadena | K2248: California | L2248: 91104 | M2248: West | N2248: TEC-PH-10004165 | O2248: Technology | P2248: Phones | Q2248: Mitel MiVoice 5330e IP Phone | R2248: 659.976 | S2248: =SUM(R2248:R12047) -> 1759740.9 | T2248: =COUNT(R2248:R12047) -> 7554 | U2248: =IF(R2248>=500,"High","Low") -> High
... A5275: 5274 | B5275: US-2017-158309 | C5275: 43065 | D5275: 43068 | E5275: First Class | F5275: PA-19060 | G5275: Pete Armstrong | H5275: Home Office | I5275: United States | J5275: Miami | K5275: Florida | L5275: 33142 | M5275: South | N5275: OFF-BI-10000145 | O5275: Office Supplies | P5275: Binders | Q5275: Zipper Ring Binder Pockets | R5275: 3.744 | S5275: =SUM(R5275:R15074) -> 1056996 | T5275: =COUNT(R5275:R15074) -> 4527 | U5275: =IF(R5275>=500,"High","Low") -> Low
A5276: 5275 | B5276: CA-2016-162887 | C5276: 42681 | D5276: 42683 | E5276: Second Class | F5276: SV-20785 | G5276: Stewart Visinsky | H5276: Consumer | I5276: United States | J5276: Burlington | K5276: Vermont | M5276: East | N5276: FUR-CH-10000595 | O5276: Furniture | P5276: Chairs | Q5276: Safco Contoured Stacking Chairs | R5276: 715.2 | S5276: =SUM(R5276:R15075) -> 1056992.2 | T5276: =COUNT(R5276:R15075) -> 4526 | U5276: =IF(R5276>=500,"High","Low") -> High
A5277: 5276 | B5277: CA-2018-147333 | C5277: 43448 | D5277: 43454 | E5277: Standard Class | F5277: KL-16555 | G5277: Kelly Lampkin | H5277: Corporate | I5277: United States | J5277: Fayetteville | K5277: Arkansas | L5277: 72701 | M5277: South | N5277: TEC-AC-10004469 | O5277: Technology | P5277: Accessories | Q5277: Microsoft Sculpt Comfort Mouse | R5277: 159.8 | S5277: =SUM(R5277:R15076) -> 1056277 | T5277: =COUNT(R5277:R15076) -> 4525 | U5277: =IF(R5277>=500,"High","Low") -> Low
A5278: 5277 | B5278: CA-2018-147333 | C5278: 43448 | D5278: 43454 | E5278: Standard Class | F5278: KL-16555 | G5278: Kelly Lampkin | H5278: Corporate | I5278: United States | J5278: Fayetteville | K5278: Arkansas | L5278: 72701 | M5278: South | N5278: TEC-AC-10003038 | O5278: Technology | P5278: Accessories | Q5278: Kingston Digital DataTraveler 16GB USB 2.0 | R5278: 44.75 | S5278: =SUM(R5278:R15077) -> 1056117.2 | T5278: =COUNT(R5278:R15077) -> 4524 | U5278: =IF(R5278>=500,"High","Low") -> Low
A5279: 5278 | B5279: CA-2015-113859 | C5279: 42260 | D5279: 42264 | E5279: Standard Class | F5279: BC-11125 | G5279: Becky Castell | H5279: Home Office | I5279: United States | J5279: Odessa | K5279: Texas | L5279: 79762 | M5279: Central | N5279: FUR-CH-10004698 | O5279: Furniture | P5279: Chairs | Q5279: Padded Folding Chairs, Black, 4/Carton | R5279: 340.116 | S5279: =SUM(R5279:R15078) -> 1056072.5 | T5279: =COUNT(R5279:R15078) -> 4523 | U5279: =IF(R5279>=500,"High","Low") -> Low
A5280: 5279 | B5280: CA-2015-159681 | C5280: 42345 | D5280: 42351 | E5280: Standard Class | F5280: PO-18850 | G5280: Patrick O'Brill | H5280: Consumer | I5280: United States | J5280: Virginia Beach | K5280: Virginia | L5280: 23464 | M5280: South | N5280: OFF-PA-10003641 | O5280: Office Supplies | P5280: Paper | Q5280: Xerox 1909 | R5280: 105.52 | S5280: =SUM(R5280:R15079) -> 1055732.4 | T5280: =COUNT(R5280:R15079) -> 4522 | U5280: =IF(R5280>=500,"High","Low") -> Low
A5281: 5280 | B5281: US-2018-104094 | C5281: 43350 | D5281: 43354 | E5281: Standard Class | F5281: AG-10675 | G5281: Anna Gayman | H5281: Consumer | I5281: United States | J5281: Milwaukee | K5281: Wisconsin | L5281: 53209 | M5281: Central | N5281: TEC-AC-10002134 | O5281: Technology | P5281: Accessories | Q5281: Rosewill 107 Normal Keys USB Wired Standard Keyboard | R5281: 13.48 | S5281: =SUM(R5281:R15080) -> 1055626.8 | T5281: =COUNT(R5281:R15080) -> 4521 | U5281: =IF(R5281>=500,"High","Low") -> Low
A5282: 5281 | B5282: CA-2018-152709 | C5282: 43380 | D5282: 43385 | E5282: Standard Class | F5282: DB-13210 | G5282: Dean Braden | H5282: Consumer | I5282: United States | J5282: Detroit | K5282: Michigan | L5282: 48234 | M5282: Central | N5282: OFF-ST-10001837 | O5282: Office Supplies | P5282: Storage | Q5282: SAFCO Mobile Desk Side File, Wire Frame | R5282: 85.52 | S5282: =SUM(R5282:R15081) -> 1055613.4 | T5282: =COUNT(R5282:R15081) -> 4520 | U5282: =IF(R5282>=500,"High","Low") -> Low
A5283: 5282 | B5283: CA-2016-105158 | C5283: 42618 | D5283: 42623 | E5283: Standard Class | F5283: SP-20860 | G5283: Sung Pak | H5283: Corporate | I5283: United States | J5283: Rochester | K5283: Minnesota | L5283: 55901 | M5283: Central | N5283: FUR-FU-10001706 | O5283: Furniture | P5283: Furnishings | Q5283: Longer-Life Soft White Bulbs | R5283: 6.16 | S5283: =SUM(R5283:R15082) -> 1055527.8 | T5283: =COUNT(R5283:R15082) -> 4519 | U5283: =IF(R5283>=500,"High","Low") -> Low
A5284: 5283 | B5284: CA-2016-105158 | C5284: 42618 | D5284: 42623 | E5284: Standard Class | F5284: SP-20860 | G5284: Sung Pak | H5284: Corporate | I5284: United States | J5284: Rochester | K5284: Minnesota | L5284: 55901 | M5284: Central | N5284: OFF-PA-10001970 | O5284: Office Supplies | P5284: Paper | Q5284: Xerox 1881 | R5284: 36.84 | S5284: =SUM(R5284:R15083) -> 1055521.7 | T5284: =COUNT(R5284:R15083) -> 4518 | U5284: =IF(R5284>=500,"High","Low") -> Low
A5285: 5284 | B5285: CA-2015-133424 | C5285: 42093 | D5285: 42098 | E5285: Standard Class | F5285: Dl-13600 | G5285: Dorris liebe | H5285: Corporate | I5285: United States | J5285: Seattle | K5285: Washington | L5285: 98105 | M5285: West | N5285: OFF-ST-10002957 | O5285: Office Supplies | P5285: Storage | Q5285: Sterilite Show Offs Storage Containers | R5285: 15.84 | S5285: =SUM(R5285:R15084) -> 1055484.8 | T5285: =COUNT(R5285:R15084) -> 4517 | U5285: =IF(R5285>=500,"High","Low") -> Low
A5286: 5285 | B5286: CA-2015-133424 | C5286: 42093 | D5286: 42098 | E5286: Standard Class | F5286: Dl-13600 | G5286: Dorris liebe | H5286: Corporate | I5286: United States | J5286: Seattle | K5286: Washington | L5286: 98105 | M5286: West | N5286: OFF-LA-10002312 | O5286: Office Supplies | P5286: Labels | Q5286: Avery 490 | R5286: 44.4 | S5286: =SUM(R5286:R15085) -> 1055469 | T5286: =COUNT(R5286:R15085) -> 4516 | U5286: =IF(R5286>=500,"High","Low") -> Low
A5287: 5286 | B5287: CA-2018-105991 | C5287: 43225 | D5287: 43226 | E5287: First Class | F5287: LH-17020 | G5287: Lisa Hazard | H5287: Consumer | I5287: United States | J5287: Louisville | K5287: Colorado | L5287: 80027 | M5287: West | N5287: OFF-EN-10002600 | O5287: Office Supplies | P5287: Envelopes | Q5287: Redi-Strip #10 Envelopes, 4 1/8 x 9 1/2 | R5287: 21.24 | S5287: =SUM(R5287:R15086) -> 1055424.6 | T5287: =COUNT(R5287:R15086) -> 4515 | U5287: =IF(R5287>=500,"High","Low") -> Low
...

Sheet KPI Analysis
A1: KPI Name | B1: Values
A2: Total Sales | B2: =SUM(train!R2:R9801) -> 2261536.8
A3: Total Orders | B3: =COUNTA(_xlfn.UNIQUE(train!B2:B9801)) -> 4922
A4: Total Customers | B4: =COUNTA(_xlfn.UNIQUE(train!F2:F9801)) -> 793
A5: Total Products | B5: =COUNTA(_xlfn.UNIQUE(train!N2:N9801)) -> 1861
A6: Average Order Value | B6: =B2/B3 -> 459.47517
A7: West Region Sales | B7: =SUMIFS(train!R2:R9801,train!M2:M9801,"West") -> 710219.68
A8: Technology Sales | B8: =SUMIFS(train!R2:R9801,train!O2:O9801,"Technology") -> 827455.87
